Workbook

Sheet QUOTATION
C1: HI - TECH SOLAR SOLUTION Solutions You Can Trust.
I5: Date: | J5: =TODAY() -> 46151
C6: GSTIN : 24AAPFH9566D1Z1
A7: OFFICE - 2nd Floor Gujarat Light, Nr Mahila Police Station, Godhra Road, Dahod - 389151
A9: Customer Information
A11: Name : | C11: Dr Aashish | G11: Meter Phase : | I11: Three Phase
A13: Adrees : | C13: Govind Nagar | G13: Consumer Num :
A15: Contact Number : | G15: Discom : | I15: MGVCL
A17: Description of Services:
A18: We propose to provide the following services for the installation of a solar plant:
A19: Design and Engineering: Our team of experts will design a customized solar plant tailored to your energy needs and site specifications. Procurement of Materials: We will procure high-quality solar panels, inverters, mounting structures, and other necessary components from reputable manufacturers. Installation: Our skilled technicians will carry out the installation of the solar panels, inverters, and associated equipment with precision and efficiency. Testing and Commissioning: We will conduct rigorous testing procedures to ensure the proper functioning of the solar plant before commissioning it for regular operation. Training and Support: We will provide training sessions for your staff on the operation and maintenance of the solar plant. Additionally, we offer ongoing technical support and maintenance services.
A35: Project Details: | F35: Proposed Solution:
A37: Type of Solar Plant: | C37: ON GRID | F37: System Size: | H37: 3 | I37: kw
A39: Location: | C39: home | F39: System Type : | H39: ON GRID
A41: Available Roof Space: | C41: 1500 | D41: sqft | F41: Type of Solar Panels: | H41: TOPCON BI-FACIAL
A43: Unit Consumption: | C43: 0 | D43: /Month | E43: AVG | F43: Inverter Type: | H43: ON GRID
A45: Desired System Size: | C45: 0 | F45: Required Area: | H45: =CONCATENATE(H37*60, ,DATA!N6) -> 180Sqft
A47: System Orientation: | C47: Roof Top | F47: Required Structure Hight | H47: 6-8 | I47: Feet
A49: REMARKS :
A51: A Billing of Quantities
A53: Sr No | B53: Item Name | D53: Make | F53: Description | I53: Unit | J53: Quantity
A54: 1 | B54: Solar Module | D54: PAHAL SOLAR | F54: 600 WP BI - FACIAL Module 30 Year Of Generation Warranty | I54: Nos | J54: =H37*1000/600 -> 5
A57: 2 | B57: Inverter | D57: SUNGROW | F57: 8 Years warranty From Company | I57: Nos | J57: 1
A60: 3 | B60: ACDB/DCDB Box | D60: MCB :-Schneider SPD ;-Finder | F60: MNRE/Indian Electrical Standard complied | I60: Set | J60: 1
A63: 4 | B63: Lighting Arrestor and Earthing Set | D63: Reputed Brand | F63: MNRE/Indian Electrical Standard complied | I63: Set | J63: 1
A66: 5 | B66: Module Mounting Structure | D66: HINDUSTAR 60 Micrones | F66: Hot Dip Galvanized with appropriate analysis for Load/Wind speed | I66: Set | J66: SET
A70: Electrical Item BOQ
B71: COMPONENT | E71: UPTO 4 KW | G71: 4.01 TO 5.99 KW | I71: 6 KW TO 9.9 KW
A72: 6 | B72: AC CABLE - APAAR | E72: 10 MTR | G72: 10 MTR | I72: 21 MTR
A73: 7 | B73: EARTHING CABLE - INDOCAB | E73: 50 MTR | G73: 50 MTR | I73: 50 MTR
A74: 8 | B74: LA CABLE - KANBERY | E74: 20 MTR | G74: 20 MTR | I74: 20 MTR
A75: 9 | B75: DC CABLE - HAVELLS | E75: 40 MTR | G75: 60 MTR | I75: 60 MTR
A76: 10 | B76: CONDUIT PIPE | E76: 20 NOS | G76: 20 NOS | I76: 20 NOS
A77: 11 | B77: ELBOW | E77: 20 NOS | G77: 20 NOS | I77: 20 NOS
A78: 12 | B78: TEE | E78: 5 NOS | G78: 5 NOS | I78: 5 NOS
A80: 10 | B80: Civil Works | F80: Foundation Block
A83: 11 | B83: Installation and Commissioning | F83: Hi – Tech Solar Solution Scope
A100: Solar RoofTop System Pricing
A102: Sr No | B102: Item Name | E102: Quantity | F102: Unit | G102: Price / Unit | I102: Amount | K102: adani topcon | L102: adani bi facial | M102: pahal topcon
A103: 1 | B103: Solar Power Generating System Rate with Incluid GST@5.7% | E103: =H37 -> 3 | F103: KW | G103: =INDEX('PL Pahal (TOPCON)'!A10:H24,MATCH(QUOTATION!H37,'PL Pahal (TOPCON)'!D10:D19,1),5) -> 48565.044 | I103: =G103*E103 -> 145695.13 | K103: =INDEX('Price List (TOPCON)'!A10:H19,MATCH(QUOTATION!H37,'Price List (TOPCON)'!D10:D19,1),5) -> 54543.092 | L103: =INDEX('Price List (BI-FACIAL)'!A10:H24,MATCH(QUOTATION!H37,'Price List (BI-FACIAL)'!D10:D24,1),5) -> 51257.448 | M103: =INDEX('PL Pahal (TOPCON)'!A10:H24,MATCH(QUOTATION!H37,'PL Pahal (TOPCON)'!D10:D19,1),5) -> 48565.044
...

Sheet Price List (BI-FACIAL)
M1: KW
A2: Quotation / Price List For Residential RTS System Under PM : Surya Ghar Muft Bijli Yojna | M2: SOLAR PLANT BOQ | BA2: Quotation / Price List For Residential RTS System Under PM : Surya Ghar Muft Bijli Yojna
A3: Name : | H3: Consumer No : | BA3: Name : | BH3: Consumer No :
A5: Address: | H5: Contact No: | M5: ITEMS | N5: MODULE | O5: INVERTER | P5: STRUCTURE | W5: ACDB | X5: DCDB | Y5: CABLING | AJ5: EARTHING KIT | AK5: CIVIL WORK | AL5: TRANSPORT | AM5: METER FEES | AN5: ELECTRIFICATION | AO5: FABRICATION | AP5: OTHER MISC. | AQ5: TOTAL | AR5: COMISSIONING CHARGES | AS5: TAXABLE VALUE | AT5: GST (70%) | AU5: GST (5.7%) | AV5: GRAND TOTAL | BA5: Address: | BH5: Contact No:
B8: Type of Solar Panels | E8: Solar RoofTop System Pricing | I8: System generation & Revenue Details | L8: Structure BOQ | P8: 60 x 40 HDGI PIPE | Q8: 40 X 40 HDGI PIPE | R8: BASE PLATE 125X125 4 MM | S8: J BOULT | T8: WEDGE ANCORE BOULT | U8: CHEMICAL BOTTLE | V8: TOTAL | Y8: AC -2CX2.5 SQMM | Z8: DC -1CX2.5 SQMM | AA8: AC -2CX4.0 SQMM | AB8: DC -1CX4 SQMM | AC8: AC - 4CX4SQMM | AD8: ERT - 1CX2.5 SQMM | AE8: ERT - 1CX4 SQMM | AF8: L.A - 1CX16SQMM | AG8: 20MM PIPE | AH8: 25MM PIPE | AI8: TOTAL | BB8: Type of Solar Panels | BE8: Solar RoofTop System Pricing | BI8: System generation & Revenue Details | BL8: Structure BOQ
A9: SR NO | B9: No of Module | C9: Module Wattage | D9: DC Capacity (kw) | E9: Discover Rate | F9: Total (Inc.GST) | G9: Subsidy | H9: Basic Plant Cost (-subsidy rate) | I9: Unit Generation / Day | J9: 2 Months Generation (Unit) | K9: 2 Months Saving (INR) | L9: No of HDPGI Pipe Incluid Size(60 x 40) & (40 x 40) | M9: RATE | N9: 24.3 | O9: 5 | P9: 80 | Q9: 80 | R9: 35 | S9: 13 | T9: 10 | U9: 850 | W9: 0.4 | X9: 0.4 | Y9: 65 | Z9: 40 | AA9: 90 | AB9: 53.5 | AC9: 200 | AD9: 30 | AE9: 45 | AF9: 18 | AG9: 60 | AH9: 75 | AJ9: 1200 | AK9: 400 | AL9: 400 | AM9: 0 | AN9: 600 | AO9: 1100 | AP9: 1000 | AR9: 0.2 | AT9: 0.05 | AU9: 0.18 | BA9: SR NO | BB9: No of Module | BC9: Module Wattage | BD9: DC Capacity (kw) | BE9: Discover Rate | BF9: Total (Inc.GST @ 5.7%) | BG9: Subsidy | BH9: Basic Plant Cost (-subsidy rate) | BI9: Unit Generation / Day | BJ9: 2 Months Generation (Unit) | BK9: 2 Months Saving (INR) | BL9: No of HDPGI Pipe Incluid Size(60 x 40) & (40 x 40)
A10: 1 | B10: 4 | C10: 550 | D10: =C10*B10/1000 -> 2.2 | E10: =F10/D10 -> 55656.612 | F10: 122444.55 | G10: =60000+(18000*(D10-2)) -> 63600 | H10: =F10-G10 -> 58844.546 | I10: =5*D10 -> 11 | J10: =I10*60 -> 660 | K10: =J10*8 -> 5280 | L10: 3 | M10: =CONCATENATE(D10,$M$1) -> 2.2 KW | N10: =$N$9*(D10*1000) -> 53460 | O10: 15300 | P10: =L10*18*$P$9 -> 4320 | Q10: =L10*15*$Q$9 -> 3600 | R10: =L10*2*$R$9 -> 210 | S10: =B10*4*$S$9 -> 208 | T10: =L10*8*$T$9 -> 240 | U10: =$U$9/2 -> 425 | V10: =SUM(P10:U10) -> 9003 | W10: 1200 | X10: =$X$9*(D10*1000) -> 880 | Y10: =$D$28*$Y$9 -> 975 | Z10: =$D$29*$Z$9 -> 1600 | AA10: 0 | AB10: 0 | AC10: 0 | AD10: =$D$30*$AD$9 -> 2100 | AE10: 0 | AF10: =$D$31*$AF$9 -> 360 | AG10: =$D$32*$AG$9 -> 1200 | AH10: 0 | AI10: =SUM(Y10:AH10) -> 6235 | AJ10: =AJ9 -> 1200 | AK10: 1500 | AL10: =AL9 -> 400 | AM10: 0 | AN10: =$AN$9*D10 -> 1320 | AO10: 3200 | AP10: =D10*$AP$9 -> 2200 | AQ10: =SUM(N10:AO10)-AI10-V10 -> 93698 | AR10: =AQ10*$AR$9 -> 18739.6 | AS10: =SUM(AQ10:AR10) -> 112437.6 | AT10: =(AS10*70%)*$AT$9 -> 3935.316 | AU10: =(AS10*30%)*$AU$9 -> 6071.6304 | AV10: =SUM(AS10:AU10) -> 122444.55 | AW10: =AV10-F10 -> 0 | AX10: 15639.15 | AY10: =AX10-(3000*BD10) -> 9099.15 | BA10: 1 | BB10: 4 | BC10: 545 | BD10: =BC10*BB10/1000 -> 2.18 | BE10: =BF10/BD10 -> 58135.073 | BF10: 126734.46 | BG10: =60000+(18000*(BD10-2)) -> 63240 | BH10: =BF10-BG10 -> 63494.459 | BI10: =5*BD10 -> 10.9 | BJ10: =BI10*60 -> 654 | BK10: =BJ10*8 -> 5232 | BL10: 3
A11: 2 | B11: 5 | C11: 550 | D11: =C11*B11/1000 -> 2.75 | E11: =F11/D11 -> 51257.448 | F11: 140957.98 | G11: =60000+(18000*(D11-2)) -> 73500 | H11: =F11-G11 -> 67457.982 | I11: =5*D11 -> 13.75 | J11: =I11*60 -> 825 | K11: =J11*8 -> 6600 | L11: 3 | M11: =CONCATENATE(D11,$M$1) -> 2.75 KW | N11: =$N$9*(D11*1000) -> 66825 | O11: 15500 | P11: =L11*18*$P$9 -> 4320 | Q11: =L11*15*$Q$9 -> 3600 | R11: =L11*2*$R$9 -> 210 | S11: =B11*4*$S$9 -> 260 | T11: =L11*8*$T$9 -> 240 | U11: =$U$9/2 -> 425 | V11: =SUM(P11:U11) -> 9055 | W11: 1200 | X11: =$X$9*(D11*1000) -> 1100 | Y11: =$D$28*$Y$9 -> 975 | Z11: =$D$29*$Z$9 -> 1600 | AA11: 0 | AB11: 0 | AC11: 0 | AD11: =$D$30*$AD$9 -> 2100 | AE11: 0 | AF11: =$D$31*$AF$9 -> 360 | AG11: =$D$32*$AG$9 -> 1200 | AH11: 0 | AI11: =SUM(Y11:AH11) -> 6235 | AJ11: =AJ10 -> 1200 | AK11: 1500 | AL11: =AL10 -> 400 | AM11: 0 | AN11: =$AN$9*D11 -> 1650 | AO11: 3200 | AP11: =D11*$AP$9 -> 2750 | AQ11: =SUM(N11:AO11)-AI11-V11 -> 107865 | AR11: =AQ11*$AR$9 -> 21573 | AS11: =SUM(AQ11:AR11) -> 129438 | AT11: =(AS11*70%)*$AT$9 -> 4530.33 | AU11: =(AS11*30%)*$AU$9 -> 6989.652 | AV11: =SUM(AS11:AU11) -> 140957.98 | AW11: =AV11-F11 -> 0 | AX11: 17831.438 | AY11: =AX11-(3000*BD11) -> 9656.4375 | BA11: 2 | BB11: 5 | BC11: 545 | BD11: =BC11*BB11/1000 -> 2.725 | BE11: =BF11/BD11 -> 53027.532 | BF11: 144500.03 | BG11: =60000+(18000*(BD11-2)) -> 73050 | BH11: =BF11-BG11 -> 71450.026 | BI11: =5*BD11 -> 13.625 | BJ11: =BI11*60 -> 817.5 | BK11: =BJ11*8 -> 6540 | BL11: 3
A12: 3 | B12: 6 | C12: 550 | D12: =C12*B12/1000 -> 3.3 | E12: =F12/D12 -> 48653.352 | F12: 160556.06 | G12: 78000 | H12: =F12-G12 -> 82556.062 | I12: =5*D12 -> 16.5 | J12: =I12*60 -> 990 | K12: =J12*8 -> 7920 | L12: 3 | M12: =CONCATENATE(D12,$M$1) -> 3.3 KW | N12: =$N$9*(D12*1000) -> 80190 | O12: 15500 | P12: =L12*18*$P$9 -> 4320 | Q12: =L12*15*$Q$9 -> 3600 | R12: =L12*2*$R$9 -> 210 | S12: =B12*4*$S$9 -> 312 | T12: =L12*8*$T$9 -> 240 | U12: =$U$9/2 -> 425 | V12: =SUM(P12:U12) -> 9107 | W12: =$W$9*(D12*1000) -> 1320 | X12: =$X$9*(D12*1000) -> 1320 | Y12: =$D$28*$Y$9 -> 975 | Z12: =$D$29*$Z$9 -> 1600 | AA12: 0 | AB12: 0 | AC12: 0 | AD12: =$D$30*$AD$9 -> 2100 | AE12: 0 | AF12: =$D$31*$AF$9 -> 360 | AG12: =$D$32*$AG$9 -> 1200 | AH12: 0 | AI12: =SUM(Y12:AH12) -> 6235 | AJ12: =AJ11 -> 1200 | AK12: =$AK$9*D12*1.5 -> 1980 | AL12: =AL11 -> 400 | AM12: 0 | AN12: =$AN$9*D12 -> 1980 | AO12: =$AO$9*D12 -> 3630 | AP12: =D12*$AP$9 -> 3300 | AQ12: =SUM(N12:AO12)-AI12-V12 -> 122862 | AR12: =AQ12*$AR$9 -> 24572.4 | AS12: =SUM(AQ12:AR12) -> 147434.4 | AT12: =(AS12*70%)*$AT$9 -> 5160.204 | AU12: =(AS12*30%)*$AU$9 -> 7961.4576 | AV12: =SUM(AS12:AU12) -> 160556.06 | AW12: =AV12-F12 -> 0 | AX12: 20264.55 | AY12: =AX12-(3000*BD12) -> 10454.55 | BA12: 3 | BB12: 6 | BC12: 545 | BD12: =BC12*BB12/1000 -> 3.27 | BE12: =BF12/BD12 -> 50219.314 | BF12: 164217.16 | BG12: 78000 | BH12: =BF12-BG12 -> 86217.158 | BI12: =5*BD12 -> 16.35 | BJ12: =BI12*60 -> 981 | BK12: =BJ12*8 -> 7848 | BL12: 3
A13: 4 | B13: 7 | C13: 550 | D13: =C13*B13/1000 -> 3.85 | E13: =F13/D13 -> 49890.569 | F13: 192078.69 | G13: 78000 | H13: =F13-G13 -> 114078.69 | I13: =5*D13 -> 19.25 | J13: =I13*60 -> 1155 | K13: =J13*8 -> 9240 | L13: 3 | M13: =CONCATENATE(D13,$M$1) -> 3.85 KW | N13: =$N$9*(D13*1000) -> 93555 | O13: 24500 | P13: =L13*18*$P$9 -> 4320 | Q13: =L13*15*$Q$9 -> 3600 | R13: =L13*2*$R$9 -> 210 | S13: =B13*4*$S$9 -> 364 | T13: =L13*8*$T$9 -> 240 | U13: =$U$9/2 -> 425 | V13: =SUM(P13:U13) -> 9159 | W13: =$W$9*(D13*1000) -> 1540 | X13: =$X$9*(D13*1000) -> 1540 | Y13: =$D$28*$Y$9 -> 975 | Z13: =$D$29*$Z$9 -> 1600 | AA13: 0 | AB13: 0 | AC13: 0 | AD13: =$D$30*$AD$9 -> 2100 | AE13: 0 | AF13: =$D$31*$AF$9 -> 360 | AG13: =$D$32*$AG$9 -> 1200 | AH13: 0 | AI13: =SUM(Y13:AH13) -> 6235 | AJ13: =AJ12 -> 1200 | AK13: =$AK$9*D13*1.5 -> 2310 | AL13: =AL12 -> 400 | AM13: 0 | AN13: =$AN$9*D13 -> 2310 | AO13: =$AO$9*D13 -> 4235 | AP13: =D13*$AP$9 -> 3850 | AQ13: =SUM(N13:AO13)-AI13-V13 -> 146984 | AR13: =AQ13*$AR$9 -> 29396.8 | AS13: =SUM(AQ13:AR13) -> 176380.8 | AT13: =(AS13*70%)*$AT$9 -> 6173.328 | AU13: =(AS13*30%)*$AU$9 -> 9524.5632 | AV13: =SUM(AS13:AU13) -> 192078.69 | AW13: =AV13-F13 -> 0 | AX13: 24565.725 | AY13: =AX13-(3000*BD13) -> 13120.725 | BA13: 4 | BB13: 7 | BC13: 545 | BD13: =BC13*BB13/1000 -> 3.815 | BE13: =BF13/BD13 -> 52181.506 | BF13: 199072.45 | BG13: 78000 | BH13: =BF13-BG13 -> 121072.45 | BI13: =5*BD13 -> 19.075 | BJ13: =BI13*60 -> 1144.5 | BK13: =BJ13*8 -> 9156 | BL13: 3
A14: 5 | B14: 8 | C14: 550 | D14: =C14*B14/1000 -> 4.4 | E14: =F14/D14 -> 48145.482 | F14: 211840.12 | G14: 78000 | H14: =F14-G14 -> 133840.12 | I14: =5*D14 -> 22 | J14: =I14*60 -> 1320 | K14: =J14*8 -> 10560 | L14: 3 | M14: =CONCATENATE(D14,$M$1) -> 4.4 KW | N14: =$N$9*(D14*1000) -> 106920 | O14: 24500 | P14: =L14*18*$P$9 -> 4320 | Q14: =L14*15*$Q$9 -> 3600 | R14: =L14*2*$R$9 -> 210 | S14: =B14*4*$S$9 -> 416 | T14: =L14*8*$T$9 -> 240 | U14: =$U$9/2 -> 425 | V14: =SUM(P14:U14) -> 9211 | W14: =$W$9*(D14*1000) -> 1760 | X14: =$X$9*(D14*1000) -> 1760 | Y14: =$D$28*$Y$9 -> 975 | Z14: =$D$29*$Z$9 -> 1600 | AA14: 0 | AB14: 0 | AC14: 0 | AD14: =$D$30*$AD$9 -> 2100 | AE14: 0 | AF14: =$D$31*$AF$9 -> 360 | AG14: =$D$32*$AG$9 -> 1200 | AH14: 0 | AI14: =SUM(Y14:AH14) -> 6235 | AJ14: =AJ13 -> 1200 | AK14: =$AK$9*D14*1.5 -> 2640 | AL14: =AL13 -> 400 | AM14: 0 | AN14: =$AN$9*D14 -> 2640 | AO14: =$AO$9*D14 -> 4840 | AP14: =D14*$AP$9 -> 4400 | AQ14: =SUM(N14:AO14)-AI14-V14 -> 162106 | AR14: =AQ14*$AR$9 -> 32421.2 | AS14: =SUM(AQ14:AR14) -> 194527.2 | AT14: =(AS14*70%)*$AT$9 -> 6808.452 | AU14: =(AS14*30%)*$AU$9 -> 10504.469 | AV14: =SUM(AS14:AU14) -> 211840.12 | AW14: =AV14-F14 -> 0 | AX14: 27516.9 | AY14: =AX14-(3000*BD14) -> 14436.9 | BA14: 5 | BB14: 8 | BC14: 545 | BD14: =BC14*BB14/1000 -> 4.36 | BE14: =BF14/BD14 -> 47578.009 | BF14: =F14-(1000*D14) -> 207440.12 | BG14: 78000 | BH14: =BF14-BG14 -> 129440.12 | BI14: =5*BD14 -> 21.8 | BJ14: =BI14*60 -> 1308 | BK14: =BJ14*8 -> 10464 | BL14: 3
A15: 6 | B15: 9 | C15: 550 | D15: =C15*B15/1000 -> 4.95 | E15: =F15/D15 -> 49550.952 | F15: 245277.21 | G15: 78000 | H15: =F15-G15 -> 167277.21 | I15: =5*D15 -> 24.75 | J15: =I15*60 -> 1485 | K15: =J15*8 -> 11880 | L15: 4 | M15: =CONCATENATE(D15,$M$1) -> 4.95 KW | N15: =$N$9*(D15*1000) -> 120285 | O15: 29000 | P15: =L15*18*$P$9 -> 5760 | Q15: =L15*15*$Q$9 -> 4800 | R15: =L15*2*$R$9 -> 280 | S15: =B15*4*$S$9 -> 468 | T15: =L15*8*$T$9 -> 320 | U15: =$U$9/2 -> 425 | V15: =SUM(P15:U15) -> 12053 | W15: =$W$9*(D15*1000) -> 1980 | X15: =$X$9*(D15*1000) -> 1980 | Y15: 0 | Z15: 0 | AA15: =$H$28*$AA$9 -> 1350 | AB15: =$H$29*$AB$9 -> 2675 | AC15: 0 | AD15: 0 | AE15: =$H$30*$AE$9 -> 3150 | AF15: =$H$31*$AF$9 -> 360 | AG15: 0 | AH15: =$H$32*$AH$9 -> 1875 | AI15: =SUM(Y15:AH15) -> 9410 | AJ15: =AJ14 -> 1200 | AK15: =$AK$9*D15*1.5 -> 2970 | AL15: =AL14 -> 400 | AM15: 0 | AN15: =$AN$9*D15 -> 2970 | AO15: =$AO$9*D15 -> 5445 | AP15: =D15*$AP$9 -> 4950 | AQ15: =SUM(N15:AO15)-AI15-V15 -> 187693 | AR15: =AQ15*$AR$9 -> 37538.6 | AS15: =SUM(AQ15:AR15) -> 225231.6 | AT15: =(AS15*70%)*$AT$9 -> 7883.106 | AU15: =(AS15*30%)*$AU$9 -> 12162.506 | AV15: =SUM(AS15:AU15) -> 245277.21 | AW15: =AV15-F15 -> 0 | AX15: 31143.075 | AY15: =AX15-(3000*BD15) -> 16428.075 | BA15: 6 | BB15: 9 | BC15: 545 | BD15: =BC15*BB15/1000 -> 4.905 | BE15: =BF15/BD15 -> 48996.374 | BF15: =F15-(1000*D15) -> 240327.21 | BG15: 78000 | BH15: =BF15-BG15 -> 162327.21 | BI15: =5*BD15 -> 24.525 | BJ15: =BI15*60 -> 1471.5 | BK15: =BJ15*8 -> 11772 | BL15: 4
A16: 7 | B16: 10 | C16: 550 | D16: =C16*B16/1000 -> 5.5 | E16: =F16/D16 -> 48188.844 | F16: 265038.64 | G16: 78000 | H16: =F16-G16 -> 187038.64 | I16: =5*D16 -> 27.5 | J16: =I16*60 -> 1650 | K16: =J16*8 -> 13200 | L16: 4 | M16: =CONCATENATE(D16,$M$1) -> 5.5 KW | N16: =$N$9*(D16*1000) -> 133650 | O16: 29000 | P16: =L16*18*$P$9 -> 5760 | Q16: =L16*15*$Q$9 -> 4800 | R16: =L16*2*$R$9 -> 280 | S16: =B16*4*$S$9 -> 520 | T16: =L16*8*$T$9 -> 320 | U16: =$U$9/2 -> 425 | V16: =SUM(P16:U16) -> 12105 | W16: =$W$9*(D16*1000) -> 2200 | X16: =$X$9*(D16*1000) -> 2200 | Y16: 0 | Z16: 0 | AA16: =$H$28*$AA$9 -> 1350 | AB16: =$H$29*$AB$9 -> 2675 | AC16: 0 | AD16: 0 | AE16: =$H$30*$AE$9 -> 3150 | AF16: =$H$31*$AF$9 -> 360 | AG16: 0 | AH16: =$H$32*$AH$9 -> 1875 | AI16: =SUM(Y16:AH16) -> 9410 | AJ16: =AJ15 -> 1200 | AK16: =$AK$9*D16*1.5 -> 3300 | AL16: =AL15 -> 400 | AM16: 0 | AN16: =$AN$9*D16 -> 3300 | AO16: =$AO$9*D16 -> 6050 | AP16: =D16*$AP$9 -> 5500 | AQ16: =SUM(N16:AO16)-AI16-V16 -> 202815 | AR16: =AQ16*$AR$9 -> 40563 | AS16: =SUM(AQ16:AR16) -> 243378 | AT16: =(AS16*70%)*$AT$9 -> 8518.23 | AU16: =(AS16*30%)*$AU$9 -> 13142.412 | AV16: =SUM(AS16:AU16) -> 265038.64 | AW16: =AV16-F16 -> 0 | AX16: 34094.25 | AY16: =AX16-(3000*BD16) -> 17744.25 | BA16: 7 | BB16: 10 | BC16: 545 | BD16: =BC16*BB16/1000 -> 5.45 | BE16: =BF16/BD16 -> 47621.769 | BF16: =F16-(1000*D16) -> 259538.64 | BG16: 78000 | BH16: =BF16-BG16 -> 181538.64 | BI16: =5*BD16 -> 27.25 | BJ16: =BI16*60 -> 1635 | BK16: =BJ16*8 -> 13080 | BL16: 4
A17: 8 | B17: 11 | C17: 550 | D17: =C17*B17/1000 -> 6.05 | E17: =F17/D17 -> 47893.032 | F17: 289752.84 | G17: 78000 | H17: =F17-G17 -> 211752.84 | I17: =5*D17 -> 30.25 | J17: =I17*60 -> 1815 | K17: =J17*8 -> 14520 | L17: 5 | M17: =CONCATENATE(D17,$M$1) -> 6.05 KW | N17: =$N$9*(D17*1000) -> 147015 | O17: 30000 | P17: =L17*18*$P$9 -> 7200 | Q17: =L17*15*$Q$9 -> 6000 | R17: =L17*2*$R$9 -> 350 | S17: =B17*4*$S$9 -> 572 | T17: =L17*8*$T$9 -> 400 | U17: =$U$9/2 -> 425 | V17: =SUM(P17:U17) -> 14947 | W17: =$W$9*(D17*1000) -> 2420 | X17: =$X$9*(D17*1000) -> 2420 | Y17: 0 | Z17: 0 | AA17: =$H$28*$AA$9 -> 1350 | AB17: =$H$29*$AB$9 -> 2675 | AC17: 0 | AD17: 0 | AE17: =$H$30*$AE$9 -> 3150 | AF17: =$H$31*$AF$9 -> 360 | AG17: 0 | AH17: =$H$32*$AH$9 -> 1875 | AI17: =SUM(Y17:AH17) -> 9410 | AJ17: =AJ16 -> 1200 | AK17: =$AK$9*D17*1.5 -> 3630 | AL17: =AL16 -> 400 | AM17: 0 | AN17: =$AN$9*D17 -> 3630 | AO17: =$AO$9*D17 -> 6655 | AP17: =D17*$AP$9 -> 6050 | AQ17: =SUM(N17:AO17)-AI17-V17 -> 221727 | AR17: =AQ17*$AR$9 -> 44345.4 | AS17: =SUM(AQ17:AR17) -> 266072.4 | AT17: =(AS17*70%)*$AT$9 -> 9312.534 | AU17: =(AS17*30%)*$AU$9 -> 14367.91 | AV17: =SUM(AS17:AU17) -> 289752.84 | AW17: =AV17-F17 -> 0 | AX17: 37195.425 | AY17: =AX17-(3000*BD17) -> 19210.425 | BA17: 8 | BB17: 11 | BC17: 545 | BD17: =BC17*BB17/1000 -> 5.995 | BE17: =BF17/BD17 -> 47323.243 | BF17: =F17-(1000*D17) -> 283702.84 | BG17: 78000 | BH17: =BF17-BG17 -> 205702.84 | BI17: =5*BD17 -> 29.975 | BJ17: =BI17*60 -> 1798.5 | BK17: =BJ17*8 -> 14388 | BL17: 5
A18: 9 | B18: 12 | C18: 550 | D18: =C18*B18/1000 -> 6.6 | E18: =F18/D18 -> 47687.112 | F18: 314734.94 | G18: 78000 | H18: =F18-G18 -> 236734.94 | I18: =5*D18 -> 33 | J18: =I18*60 -> 1980 | K18: =J18*8 -> 15840 | L18: 5 | M18: =CONCATENATE(D18,$M$1) -> 6.6 KW | N18: =$N$9*(D18*1000) -> 160380 | O18: 30000 | P18: =L18*18*$P$9 -> 7200 | Q18: =L18*15*$Q$9 -> 6000 | R18: =L18*2*$R$9 -> 350 | S18: =B18*4*$S$9 -> 624 | T18: =L18*8*$T$9 -> 400 | U18: =$U$9/2 -> 425 | V18: =SUM(P18:U18) -> 14999 | W18: =$W$9*(D18*1000) -> 2640 | X18: =$X$9*(D18*1000) -> 2640 | Y18: 0 | Z18: 0 | AA18: 0 | AB18: =$L$29*$AB$9 -> 3745 | AC18: =$L$28*$AC$9 -> 3600 | AD18: 0 | AE18: =$L$30*$AE$9 -> 3150 | AF18: =$L$31*$AF$9 -> 360 | AG18: 0 | AH18: =$L$32*$AH$9 -> 2250 | AI18: =SUM(Y18:AH18) -> 13105 | AJ18: =AJ17 -> 1200 | AK18: =$AK$9*D18*1.5 -> 3960 | AL18: 700 | AM18: 0 | AN18: =$AN$9*D18 -> 3960 | AO18: =$AO$9*D18 -> 7260 | AP18: =D18*$AP$9 -> 6600 | AQ18: =SUM(N18:AO18)-AI18-V18 -> 240844 | AR18: =AQ18*$AR$9 -> 48168.8 | AS18: =SUM(AQ18:AR18) -> 289012.8 | AT18: =(AS18*70%)*$AT$9 -> 10115.448 | AU18: =(AS18*30%)*$AU$9 -> 15606.691 | AV18: =SUM(AS18:AU18) -> 314734.94 | AW18: =AV18-F18 -> 0 | AX18: 40199.1 | AY18: =AX18-(3000*BD18) -> 20579.1 | BA18: 9 | BB18: 12 | BC18: 545 | BD18: =BC18*BB18/1000 -> 6.54 | BE18: =BF18/BD18 -> 47115.434 | BF18: =F18-(1000*D18) -> 308134.94 | BG18: 78000 | BH18: =BF18-BG18 -> 230134.94 | BI18: =5*BD18 -> 32.7 | BJ18: =BI18*60 -> 1962 | BK18: =BJ18*8 -> 15696 | BL18: 5
A19: 10 | B19: 13 | C19: 550 | D19: =C19*B19/1000 -> 7.15 | E19: =F19/D19 -> 47292.635 | F19: 338142.34 | G19: 78000 | H19: =F19-G19 -> 260142.34 | I19: =5*D19 -> 35.75 | J19: =I19*60 -> 2145 | K19: =J19*8 -> 17160 | L19: 6 | M19: =CONCATENATE(D19,$M$1) -> 7.15 KW | N19: =$N$9*(D19*1000) -> 173745 | O19: 30000 | P19: =L19*18*$P$9 -> 8640 | Q19: =L19*15*$Q$9 -> 7200 | R19: =L19*2*$R$9 -> 420 | S19: =B19*4*$S$9 -> 676 | T19: =L19*8*$T$9 -> 480 | U19: =$U$9/2 -> 425 | V19: =SUM(P19:U19) -> 17841 | W19: =$W$9*(D19*1000) -> 2860 | X19: =$X$9*(D19*1000) -> 2860 | Y19: 0 | Z19: 0 | AA19: 0 | AB19: =$L$29*$AB$9 -> 3745 | AC19: =$L$28*$AC$9 -> 3600 | AD19: 0 | AE19: =$L$30*$AE$9 -> 3150 | AF19: =$L$31*$AF$9 -> 360 | AG19: 0 | AH19: =$L$32*$AH$9 -> 2250 | AI19: =SUM(Y19:AH19) -> 13105 | AJ19: =AJ18 -> 1200 | AK19: =$AK$9*D19*1.5 -> 4290 | AL19: 700 | AM19: 0 | AN19: =$AN$9*D19 -> 4290 | AO19: =$AO$9*D19 -> 7865 | AP19: =D19*$AP$9 -> 7150 | AQ19: =SUM(N19:AO19)-AI19-V19 -> 258756 | AR19: =AQ19*$AR$9 -> 51751.2 | AS19: =SUM(AQ19:AR19) -> 310507.2 | AT19: =(AS19*70%)*$AT$9 -> 10867.752 | AU19: =(AS19*30%)*$AU$9 -> 16767.389 | AV19: =SUM(AS19:AU19) -> 338142.34 | AW19: =AV19-F19 -> 0 | AX19: 43150.275 | AY19: =AX19-(3000*BD19) -> 21895.275 | BA19: 10 | BB19: 13 | BC19: 545 | BD19: =BC19*BB19/1000 -> 7.085 | BE19: =BF19/BD19 -> 46717.338 | BF19: =F19-(1000*D19) -> 330992.34 | BG19: 78000 | BH19: =BF19-BG19 -> 252992.34 | BI19: =5*BD19 -> 35.425 | BJ19: =BI19*60 -> 2125.5 | BK19: =BJ19*8 -> 17004 | BL19: 6
A20: 11 | B20: 14 | C20: 550 | D20: =C20*B20/1000 -> 7.7 | E20: =F20/D20 -> 50129.866 | F20: 385999.97 | G20: 78000 | H20: =F20-G20 -> 307999.97 | I20: =5*D20 -> 38.5 | J20: =I20*60 -> 2310 | K20: =J20*8 -> 18480 | L20: 6 | M20: =CONCATENATE(D20,$M$1) -> 7.7 KW | N20: =$N$9*(D20*1000) -> 187110 | O20: 51500 | P20: =L20*18*$P$9 -> 8640 | Q20: =L20*15*$Q$9 -> 7200 | R20: =L20*2*$R$9 -> 420 | S20: =B20*4*$S$9 -> 728 | T20: =L20*8*$T$9 -> 480 | U20: =$U$9/2 -> 425 | V20: =SUM(P20:U20) -> 17893 | W20: =$W$9*(D20*1000) -> 3080 | X20: =$X$9*(D20*1000) -> 3080 | Y20: 0 | Z20: 0 | AA20: 0 | AB20: =$L$29*$AB$9 -> 3745 | AC20: =$L$28*$AC$9 -> 3600 | AD20: 0 | AE20: =$L$30*$AE$9 -> 3150 | AF20: =$L$31*$AF$9 -> 360 | AG20: 0 | AH20: =$L$32*$AH$9 -> 2250 | AI20: =SUM(Y20:AH20) -> 13105 | AJ20: =AJ19 -> 1200 | AK20: =$AK$9*D20*1.5 -> 4620 | AL20: 700 | AM20: 0 | AN20: =$AN$9*D20 -> 4620 | AO20: =$AO$9*D20 -> 8470 | AP20: =D20*$AP$9 -> 7700 | AQ20: =SUM(N20:AO20)-AI20-V20 -> 295378 | AR20: =AQ20*$AR$9 -> 59075.6 | AS20: =SUM(AQ20:AR20) -> 354453.6 | AT20: =(AS20*70%)*$AT$9 -> 12405.876 | AU20: =(AS20*30%)*$AU$9 -> 19140.494 | AV20: =SUM(AS20:AU20) -> 385999.97 | AW20: =AV20-F20 -> 0 | AX20: 49326.45 | AY20: =AX20-(3000*BD20) -> 26436.45 | BA20: 11 | BB20: 14 | BC20: 545 | BD20: =BC20*BB20/1000 -> 7.63 | BE20: =BF20/BD20 -> 49580.599 | BF20: =F20-(1000*D20) -> 378299.97 | BG20: 78000 | BH20: =BF20-BG20 -> 300299.97 | BI20: =5*BD20 -> 38.15 | BJ20: =BI20*60 -> 2289 | BK20: =BJ20*8 -> 18312 | BL20: 6
A21: 12 | B21: 15 | C21: 550 | D21: =C21*B21/1000 -> 8.25 | E21: =F21/D21 -> 49183.2 | F21: 405761.4 | G21: 78000 | H21: =F21-G21 -> 327761.4 | I21: =5*D21 -> 41.25 | J21: =I21*60 -> 2475 | K21: =J21*8 -> 19800 | L21: 6 | M21: =CONCATENATE(D21,$M$1) -> 8.25 KW | N21: =$N$9*(D21*1000) -> 200475 | O21: 51500 | P21: =L21*18*$P$9 -> 8640 | Q21: =L21*15*$Q$9 -> 7200 | R21: =L21*2*$R$9 -> 420 | S21: =B21*4*$S$9 -> 780 | T21: =L21*8*$T$9 -> 480 | U21: =$U$9/2 -> 425 | V21: =SUM(P21:U21) -> 17945 | W21: =$W$9*(D21*1000) -> 3300 | X21: =$X$9*(D21*1000) -> 3300 | Y21: 0 | Z21: 0 | AA21: 0 | AB21: =$L$29*$AB$9 -> 3745 | AC21: =$L$28*$AC$9 -> 3600 | AD21: 0 | AE21: =$L$30*$AE$9 -> 3150 | AF21: =$L$31*$AF$9 -> 360 | AG21: 0 | AH21: =$L$32*$AH$9 -> 2250 | AI21: =SUM(Y21:AH21) -> 13105 | AJ21: =AJ20 -> 1200 | AK21: =$AK$9*D21*1.5 -> 4950 | AL21: 700 | AM21: 0 | AN21: =$AN$9*D21 -> 4950 | AO21: =$AO$9*D21 -> 9075 | AP21: =D21*$AP$9 -> 8250 | AQ21: =SUM(N21:AO21)-AI21-V21 -> 310500 | AR21: =AQ21*$AR$9 -> 62100 | AS21: =SUM(AQ21:AR21) -> 372600 | AT21: =(AS21*70%)*$AT$9 -> 13041 | AU21: =(AS21*30%)*$AU$9 -> 20120.4 | AV21: =SUM(AS21:AU21) -> 405761.4 | AW21: =AV21-F21 -> 0 | AX21: 52277.625 | AY21: =AX21-(3000*BD21) -> 27752.625 | BA21: 12 | BB21: 15 | BC21: 545 | BD21: =BC21*BB21/1000 -> 8.175 | BE21: =BF21/BD21 -> 48625.248 | BF21: =F21-(1000*D21) -> 397511.4 | BG21: 78000 | BH21: =BF21-BG21 -> 319511.4 | BI21: =5*BD21 -> 40.875 | BJ21: =BI21*60 -> 2452.5 | BK21: =BJ21*8 -> 19620 | BL21: 6
A22: 13 | B22: 16 | C22: 550 | D22: =C22*B22/1000 -> 8.8 | E22: =F22/D22 -> 48769.182 | F22: 429168.8 | G22: 78000 | H22: =F22-G22 -> 351168.8 | I22: =5*D22 -> 44 | J22: =I22*60 -> 2640 | K22: =J22*8 -> 21120 | L22: 7 | M22: =CONCATENATE(D22,$M$1) -> 8.8 KW | N22: =$N$9*(D22*1000) -> 213840 | O22: 51500 | P22: =L22*18*$P$9 -> 10080 | Q22: =L22*15*$Q$9 -> 8400 | R22: =L22*2*$R$9 -> 490 | S22: =B22*4*$S$9 -> 832 | T22: =L22*8*$T$9 -> 560 | U22: =$U$9/2 -> 425 | V22: =SUM(P22:U22) -> 20787 | W22: =$W$9*(D22*1000) -> 3520 | X22: =$X$9*(D22*1000) -> 3520 | Y22: 0 | Z22: 0 | AA22: 0 | AB22: =$L$29*$AB$9 -> 3745 | AC22: =$L$28*$AC$9 -> 3600 | AD22: 0 | AE22: =$L$30*$AE$9 -> 3150 | AF22: =$L$31*$AF$9 -> 360 | AG22: 0 | AH22: =$L$32*$AH$9 -> 2250 | AI22: =SUM(Y22:AH22) -> 13105 | AJ22: =AJ21 -> 1200 | AK22: =$AK$9*D22*1.5 -> 5280 | AL22: 700 | AM22: 0 | AN22: =$AN$9*D22 -> 5280 | AO22: =$AO$9*D22 -> 9680 | AP22: =D22*$AP$9 -> 8800 | AQ22: =SUM(N22:AO22)-AI22-V22 -> 328412 | AR22: =AQ22*$AR$9 -> 65682.4 | AS22: =SUM(AQ22:AR22) -> 394094.4 | AT22: =(AS22*70%)*$AT$9 -> 13793.304 | AU22: =(AS22*30%)*$AU$9 -> 21281.098 | AV22: =SUM(AS22:AU22) -> 429168.8 | AW22: =AV22-F22 -> 0 | AX22: 55228.8 | AY22: =AX22-(3000*BD22) -> 29068.8 | BA22: 13 | BB22: 16 | BC22: 545 | BD22: =BC22*BB22/1000 -> 8.72 | BE22: =BF22/BD22 -> 48207.431 | BF22: =F22-(1000*D22) -> 420368.8 | BG22: 78000 | BH22: =BF22-BG22 -> 342368.8 | BI22: =5*BD22 -> 43.6 | BJ22: =BI22*60 -> 2616 | BK22: =BJ22*8 -> 20928 | BL22: 7
A23: 14 | B23: 17 | C23: 550 | D23: =C23*B23/1000 -> 9.35 | E23: =F23/D23 -> 48013.928 | F23: 448930.23 | G23: 78000 | H23: =F23-G23 -> 370930.23 | I23: =5*D23 -> 46.75 | J23: =I23*60 -> 2805 | K23: =J23*8 -> 22440 | L23: 7 | M23: =CONCATENATE(D23,$M$1) -> 9.35 KW | N23: =$N$9*(D23*1000) -> 227205 | O23: 51500 | P23: =L23*18*$P$9 -> 10080 | Q23: =L23*15*$Q$9 -> 8400 | R23: =L23*2*$R$9 -> 490 | S23: =B23*4*$S$9 -> 884 | T23: =L23*8*$T$9 -> 560 | U23: =$U$9/2 -> 425 | V23: =SUM(P23:U23) -> 20839 | W23: =$W$9*(D23*1000) -> 3740 | X23: =$X$9*(D23*1000) -> 3740 | Y23: 0 | Z23: 0 | AA23: 0 | AB23: =$L$29*$AB$9 -> 3745 | AC23: =$L$28*$AC$9 -> 3600 | AD23: 0 | AE23: =$L$30*$AE$9 -> 3150 | AF23: =$L$31*$AF$9 -> 360 | AG23: 0 | AH23: =$L$32*$AH$9 -> 2250 | AI23: =SUM(Y23:AH23) -> 13105 | AJ23: =AJ22 -> 1200 | AK23: =$AK$9*D23*1.5 -> 5610 | AL23: 700 | AM23: 0 | AN23: =$AN$9*D23 -> 5610 | AO23: =$AO$9*D23 -> 10285 | AP23: =D23*$AP$9 -> 9350 | AQ23: =SUM(N23:AO23)-AI23-V23 -> 343534 | AR23: =AQ23*$AR$9 -> 68706.8 | AS23: =SUM(AQ23:AR23) -> 412240.8 | AT23: =(AS23*70%)*$AT$9 -> 14428.428 | AU23: =(AS23*30%)*$AU$9 -> 22261.003 | AV23: =SUM(AS23:AU23) -> 448930.23 | AW23: =AV23-F23 -> 0 | AX23: 58179.975 | AY23: =AX23-(3000*BD23) -> 30384.975 | BA23: 14 | BB23: 17 | BC23: 545 | BD23: =BC23*BB23/1000 -> 9.265 | BE23: =BF23/BD23 -> 47445.249 | BF23: =F23-(1000*D23) -> 439580.23 | BG23: 78000 | BH23: =BF23-BG23 -> 361580.23 | BI23: =5*BD23 -> 46.325 | BJ23: =BI23*60 -> 2779.5 | BK23: =BJ23*8 -> 22236 | BL23: 7
A24: 15 | B24: 18 | C24: 550 | D24: =C24*B24/1000 -> 9.9 | E24: =F24/D24 -> 47974.872 | F24: 474951.23 | G24: 78000 | H24: =F24-G24 -> 396951.23 | I24: =5*D24 -> 49.5 | J24: =I24*60 -> 2970 | K24: =J24*8 -> 23760 | L24: 8 | M24: =CONCATENATE(D24,$M$1) -> 9.9 KW | N24: =$N$9*(D24*1000) -> 240570 | O24: 53500 | P24: =L24*18*$P$9 -> 11520 | Q24: =L24*15*$Q$9 -> 9600 | R24: =L24*2*$R$9 -> 560 | S24: =B24*4*$S$9 -> 936 | T24: =L24*8*$T$9 -> 640 | U24: =$U$9/2 -> 425 | V24: =SUM(P24:U24) -> 23681 | W24: =$W$9*(D24*1000) -> 3960 | X24: =$X$9*(D24*1000) -> 3960 | Y24: 0 | Z24: 0 | AA24: 0 | AB24: =$L$29*$AB$9 -> 3745 | AC24: =$L$28*$AC$9 -> 3600 | AD24: 0 | AE24: =$L$30*$AE$9 -> 3150 | AF24: =$L$31*$AF$9 -> 360 | AG24: 0 | AH24: =$L$32*$AH$9 -> 2250 | AI24: =SUM(Y24:AH24) -> 13105 | AJ24: =AJ23 -> 1200 | AK24: =$AK$9*D24*1.5 -> 5940 | AL24: 700 | AM24: 0 | AN24: =$AN$9*D24 -> 5940 | AO24: =$AO$9*D24 -> 10890 | AP24: =D24*$AP$9 -> 9900 | AQ24: =SUM(N24:AO24)-AI24-V24 -> 363446 | AR24: =AQ24*$AR$9 -> 72689.2 | AS24: =SUM(AQ24:AR24) -> 436135.2 | AT24: =(AS24*70%)*$AT$9 -> 15264.732 | AU24: =(AS24*30%)*$AU$9 -> 23551.301 | AV24: =SUM(AS24:AU24) -> 474951.23 | AW24: =AV24-F24 -> 0 | AX24: 61431.15 | AY24: =AX24-(3000*BD24) -> 32001.15 | BA24: 15 | BB24: 18 | BC24: 545 | BD24: =BC24*BB24/1000 -> 9.81 | BE24: =BF24/BD24 -> 47405.834 | BF24: =F24-(1000*D24) -> 465051.23 | BG24: 78000 | BH24: =BF24-BG24 -> 387051.23 | BI24: =5*BD24 -> 49.05 | BJ24: =BI24*60 -> 2943 | BK24: =BJ24*8 -> 23544 | BL24: 8
A25: Electrical Item BOQ | BA25: Electrical Item BOQ
A26: 2 kw to 4.5 kw | E26: 5 kw to 6 kw | I26: 6 kw to 10 kw | M26: SUNGROW | V26: SOLARYAAN | BA26: 2 kw to 4.5 kw | BE26: 5 kw to 6 kw | BI26: 6 kw to 10 kw
A27: Item | D27: Quantity(MTR) | E27: Item | H27: Quantity(MTR) | I27: Item | L27: Quantity(MTR) | M27: INV - SG3.0RS | O27: 15800 | V27: INV - SG3.0RS | X27: 14500 | BA27: Item | BD27: Quantity | BE27: Item | BH27: Quantity | BI27: Item | BL27: Quantity
A28: 2C X 2.5 SQMM CU.FLEX CABLE (AC) | D28: 15 | E28: 2C X 4 SQMM CU.FLEX CABLE (AC) | H28: 15 | I28: 4C X 4 SQMM CU.FLEX CABLE (AC) | L28: 18 | M28: INV - SG3.6RS | O28: 15800 | V28: INV - SG3.6RS | X28: 14500 | BA28: 2C X 2.5 SQMM CU.FLEX CABLE (AC) | BD28: 10 MTR | BE28: 2C X 4 SQMM CU.FLEX CABLE (AC) | BH28: 15 MTR | BI28: 3C X 4 SQMM CU.FLEX CABLE (AC) | BL28: 15 MTR
A29: 1C X 2.5 SQMM CU.FLEX CABLE (DC) | D29: 40 | E29: 1C X 4 SQMM CU.FLEX CABLE (DC) | H29: 50 | I29: 1C X 4 SQMM CU.FLEX CABLE (DC) | L29: 70 | M29: INV - SG4.0RS | O29: 24500 | V29: INV - SG4.0RS | X29: 19500 | BA29: 1C X 2.5 SQMM CU.FLEX CABLE (DC) | BD29: 40 MTR | BE29: 1C X 4 SQMM CU.FLEX CABLE (DC) | BH29: 50 MTR | BI29: 1C X 4 SQMM CU.FLEX CABLE (DC) | BL29: 60 MTR
A30: 1C X 2.5 SQMM CU.FLEX CABLE (EARTHING) | D30: 70 | E30: 1C X 4 SQMM CU.FLEX CABLE (EARTHING) | H30: 70 | I30: 1C X 4 SQMM CU.FLEX CABLE (EARTHING) | L30: 70 | M30: INV - SG5.0RS | O30: 29000 | V30: INV - SG5.0RS | X30: 25500 | BA30: 1C X 2.5 SQMM CU.FLEX CABLE (EARTHING) | BD30: 70 MTR | BE30: 1C X 4 SQMM CU.FLEX CABLE (EARTHING) | BH30: 70 MTR | BI30: 1C X 4 SQMM CU.FLEX CABLE (EARTHING) | BL30: 70 MTR
A31: 1C X 16 SQMM AL.FLEX CABLE (LA) | D31: 20 | E31: 1C X 16 SQMM AL.FLEX CABLE (LA) | H31: 20 | I31: 1C X 16 SQMM AL.FLEX CABLE (LA) | L31: 20 | M31: INV - SG6.0RS | O31: 30000 | V31: INV - SG6.0RS | X31: 26000 | BA31: 1C X 16 SQMM AL.FLEX CABLE (LA) | BD31: 20 MTR | BE31: 1C X 16 SQMM AL.FLEX CABLE (LA) | BH31: 20 MTR | BI31: 1C X 16 SQMM AL.FLEX CABLE (LA) | BL31: 20 MTR
A32: 20 MM PVC PIPE WITH SADDLE - NOS | D32: 20 | E32: 25 MM PVC PIPE WITH SADDLE - NOS | H32: 25 | I32: 25 MM PVC PIPE WITH SADDLE - NOS | L32: 30 | M32: INV - SG5.0RT | V32: INV - SG5.0RT | BA32: 20 MM PVC PIPE WITH SADDLE | BD32: 15 NOS | BE32: 25 MM PVC PIPE WITH SADDLE | BH32: 20 NOS | BI32: 25 MM PVC PIPE WITH SADDLE | BL32: 20 NOS
A33: 20 MM ELBO - NOS | D33: 15 | E33: 25 MM ELBO - NOS | H33: 20 | I33: 25 MM ELBO - NOS | L33: 20 | M33: INV - SG6.0RT | O33: 47000 | V33: INV - SG6.0RT | BA33: 20 MM ELBO | BD33: 15 NOS | BE33: 25 MM ELBO | BH33: 20 NOS | BI33: 25 MM ELBO | BL33: 20 NOS
A34: 20 MM TEE - NOS | D34: 5 | E34: 25 MM TEE - NOS | H34: 7 | I34: 25 MM TEE - NOS | L34: 7 | M34: INV - SG8.0RT | O34: 51500 | V34: INV - SG8.0RT | BA34: 20 MM TEE | BD34: 5 NOS | BE34: 25 MM TEE | BH34: 7 NOS | BI34: 25 MM TEE | BL34: 7 NOS
A35: Banking Detail | E35: Required Documents | H35: ITEM AND ITS MAKE | M35: INV - SG10RT | O35: 53500 | V35: INV - SG10RT | BA35: Banking Detail | BE35: Required Documents | BH35: ITEM AND ITS MAKE
A36: Bank Name : | C36: AU SMALL FINANCE BANK | E36: 1 | F36: ELECTRICITY BILL | H36: SOLAR MODULE | J36: ADANI BI FACIAL | BA36: Bank Name : | BC36: AU SMALL FINANCE BANK | BE36: 1 | BF36: ELECTRICITY BILL | BH36: SOLAR MODULE | BJ36: ADANI / VIKRAM / WAAREE
A37: A/C Name : | C37: HI TECH SOLAR SOLUTION | E37: 2 | F37: BANK DETAILS | H37: SOLAR INVERTER | J37: SUNGROW | BA37: A/C Name : | BC37: HI TECH SOLAR SOLUTION | BE37: 2 | BF37: BANK DETAILS | BH37: SOLAR INVERTER | BJ37: SUNGROW
A38: A/C Type : | C38: CURRENT ACCOUNT | E38: 3 | F38: AADHAR CARD | H38: ACDB & DCDB | J38: MCB :-Schneider & SPD :-Finder | BA38: A/C Type : | BC38: CURRENT ACCOUNT | BE38: 3 | BF38: AADHAR CARD | BH38: ACDB & DCDB | BJ38: MCB :-Schneider & SPD :-Finder
A39: A/C Number : | C39: 1107865152531445 | E39: 4 | F39: PAN CARD | H39: WIRES AND CABLES | J39: DC CABLE - HAVELLS | AC CABLE - APAAR | BA39: A/C Number : | BC39: 1107865152531445 | BE39: 4 | BF39: PAN CARD | BH39: WIRES AND CABLES | BJ39: APAAR / POLYCAB
A40: IFSC Code : | C40: AUBL0002158 | H40: Module Mounting Structure | J40: 60 MICRONES HDPGI (HINDUSTAR MAKE) | BA40: IFSC Code : | BC40: AUBL0002158 | BH40: Module Mounting Structure | BJ40: 60 MICRONES HDPGI
A41: Branch : | C41: DAHOD | H41: EARTHING & LA | J41: 1.5 MTR COPPER BOUNDED ROAD | BA41: Branch : | BC41: DAHOD | BH41: EARTHING & LA | BJ41: COPPER BOUNDED
A42: TEARMS AND CONDITIONS | BA42: TEARMS AND CONDITIONS
A43: 1 | B43: Described cable length in BOQ is included in standard plant rate. If length more than from described BOQ will be charged 250RS/FEET/KW Upto 4.5 kw ,350RS/FEET/KW From 4.5 to 6 kw & 450RS/FEET/KW From 6 to 10 kw as per Actual. | BA43: 1 | BB43: Described cable length in BOQ is included in standard plant rate. If length more than from described BOQ will be charged 250RS/FEET/KW Upto 4.5 kw ,350RS/FEET/KW From 4.5 to 6 kw & 450RS/FEET/KW From 6 to 10 kw as per Actual.
...

Sheet Price List (TOPCON)
M1: KW
A2: Quotation / Price List For Residential RTS System Under PM : Surya Ghar Muft Bijli Yojna | M2: SOLAR PLANT BOQ
A3: Name : | H3: Consumer No :
A5: Address: | H5: Contact No: | M5: ITEMS | N5: MODULE | O5: INVERTER | P5: STRUCTURE | W5: ACDB | X5: DCDB | Y5: CABLING | AJ5: EARTHING KIT | AK5: CIVIL WORK | AL5: TRANSPORT | AM5: METER FEES | AN5: ELECTRIFICATION | AO5: FABRICATION | AP5: OTHER MISC. | AQ5: TOTAL | AR5: COMISSIONING CHARGES | AS5: TAXABLE VALUE | AT5: GST (70%) | AU5: GST (5.7%) | AV5: GRAND TOTAL
B8: Type of Solar Panels | E8: Solar RoofTop System Pricing | I8: System generation & Revenue Details | L8: Structure BOQ | P8: 60 x 40 HDGI PIPE | Q8: 40 X 40 HDGI PIPE | R8: BASE PLATE 125X125 4 MM | S8: J BOULT | T8: WEDGE ANCORE BOULT | U8: CHEMICAL BOTTLE | V8: TOTAL | Y8: AC -2CX2.5 SQMM | Z8: DC -1CX2.5 SQMM | AA8: AC -2CX4.0 SQMM | AB8: DC -1CX4 SQMM | AC8: AC - 4CX4SQMM | AD8: ERT - 1CX2.5 SQMM | AE8: ERT - 1CX4 SQMM | AF8: L.A - 1CX16SQMM | AG8: 20MM PIPE | AH8: 25MM PIPE | AI8: TOTAL
A9: SR NO | B9: No of Module | C9: Module Wattage | D9: DC Capacity (kw) | E9: Discover Rate | F9: Total (Inc.GST @ 5.7%) | G9: Subsidy | H9: Basic Plant Cost (-subsidy rate) | I9: Unit Generation / Day | J9: 2 Months Generation (Unit) | K9: 2 Months Saving (INR) | L9: No of HDPGI Pipe Incluid Size(60 x 40) & (40 x 40) | M9: RATE | N9: 25.4 | O9: 5 | P9: 80 | Q9: 80 | R9: 35 | S9: 13 | T9: 10 | U9: 850 | W9: 0.4 | X9: 0.4 | Y9: 65 | Z9: 40 | AA9: 90 | AB9: 53.5 | AC9: 200 | AD9: 30 | AE9: 45 | AF9: 18 | AG9: 60 | AH9: 75 | AJ9: 1200 | AK9: 400 | AL9: 400 | AM9: 0 | AN9: 600 | AO9: 1100 | AP9: 1000 | AR9: 0.2 | AT9: 0.05 | AU9: 0.18
A10: 1 | B10: 4 | C10: 620 | D10: =C10*B10/1000 -> 2.48 | E10: =F10/D10 -> 54543.092 | F10: 135266.87 | G10: =60000+(18000*(D10-2)) -> 68640 | H10: =F10-G10 -> 66626.868 | I10: =5*D10 -> 12.4 | J10: =I10*60 -> 744 | K10: =J10*8 -> 5952 | L10: 3 | M10: =CONCATENATE(D10,$M$1) -> 2.48 KW | N10: =$N$9*(D10*1000) -> 62992 | O10: 15300 | P10: =L10*18*$P$9 -> 4320 | Q10: =L10*15*$Q$9 -> 3600 | R10: =L10*2*$R$9 -> 210 | S10: =B10*4*$S$9 -> 208 | T10: =L10*8*$T$9 -> 240 | U10: =$U$9/2 -> 425 | V10: =SUM(P10:U10) -> 9003 | W10: 1200 | X10: =$X$9*(D10*1000) -> 992 | Y10: =$D$23*$Y$9 -> 975 | Z10: =$D$24*$Z$9 -> 1600 | AA10: 0 | AB10: 0 | AC10: 0 | AD10: =$D$25*$AD$9 -> 2100 | AE10: 0 | AF10: =$D$26*$AF$9 -> 360 | AG10: =$D$27*$AG$9 -> 1200 | AH10: 0 | AI10: =SUM(Y10:AH10) -> 6235 | AJ10: =AJ9 -> 1200 | AK10: 1500 | AL10: =AL9 -> 400 | AM10: 0 | AN10: =$AN$9*D10 -> 1488 | AO10: 3200 | AP10: =D10*$AP$9 -> 2480 | AQ10: =SUM(N10:AO10)-AI10-V10 -> 103510 | AR10: =AQ10*$AR$9 -> 20702 | AS10: =SUM(AQ10:AR10) -> 124212 | AT10: =(AS10*70%)*$AT$9 -> 4347.42 | AU10: =(AS10*30%)*$AU$9 -> 6707.448 | AV10: =SUM(AS10:AU10) -> 135266.87 | AW10: =AV10-F10 -> 0
A11: 2 | B11: 5 | C11: 620 | D11: =C11*B11/1000 -> 3.1 | E11: =F11/D11 -> 50640.608 | F11: 156985.88 | G11: 78000 | H11: =F11-G11 -> 78985.884 | I11: =5*D11 -> 15.5 | J11: =I11*60 -> 930 | K11: =J11*8 -> 7440 | L11: 3 | M11: =CONCATENATE(D11,$M$1) -> 3.1 KW | N11: =$N$9*(D11*1000) -> 78740 | O11: 15500 | P11: =L11*18*$P$9 -> 4320 | Q11: =L11*15*$Q$9 -> 3600 | R11: =L11*2*$R$9 -> 210 | S11: =B11*4*$S$9 -> 260 | T11: =L11*8*$T$9 -> 240 | U11: =$U$9/2 -> 425 | V11: =SUM(P11:U11) -> 9055 | W11: 1200 | X11: =$X$9*(D11*1000) -> 1240 | Y11: =$D$23*$Y$9 -> 975 | Z11: =$D$24*$Z$9 -> 1600 | AA11: 0 | AB11: 0 | AC11: 0 | AD11: =$D$25*$AD$9 -> 2100 | AE11: 0 | AF11: =$D$26*$AF$9 -> 360 | AG11: =$D$27*$AG$9 -> 1200 | AH11: 0 | AI11: =SUM(Y11:AH11) -> 6235 | AJ11: =AJ10 -> 1200 | AK11: 1500 | AL11: =AL10 -> 400 | AM11: 0 | AN11: =$AN$9*D11 -> 1860 | AO11: 3200 | AP11: =D11*$AP$9 -> 3100 | AQ11: =SUM(N11:AO11)-AI11-V11 -> 120130 | AR11: =AQ11*$AR$9 -> 24026 | AS11: =SUM(AQ11:AR11) -> 144156 | AT11: =(AS11*70%)*$AT$9 -> 5045.46 | AU11: =(AS11*30%)*$AU$9 -> 7784.424 | AV11: =SUM(AS11:AU11) -> 156985.88 | AW11: =AV11-F11 -> 0
A12: 3 | B12: 6 | C12: 620 | D12: =C12*B12/1000 -> 3.72 | E12: =F12/D12 -> 51801.974 | F12: 192703.34 | G12: 78000 | H12: =F12-G12 -> 114703.34 | I12: =5*D12 -> 18.6 | J12: =I12*60 -> 1116 | K12: =J12*8 -> 8928 | L12: 3 | M12: =CONCATENATE(D12,$M$1) -> 3.72 KW | N12: =$N$9*(D12*1000) -> 94488 | O12: 24500 | P12: =L12*18*$P$9 -> 4320 | Q12: =L12*15*$Q$9 -> 3600 | R12: =L12*2*$R$9 -> 210 | S12: =B12*4*$S$9 -> 312 | T12: =L12*8*$T$9 -> 240 | U12: =$U$9/2 -> 425 | V12: =SUM(P12:U12) -> 9107 | W12: =$W$9*(D12*1000) -> 1488 | X12: =$X$9*(D12*1000) -> 1488 | Y12: =$D$23*$Y$9 -> 975 | Z12: =$D$24*$Z$9 -> 1600 | AA12: 0 | AB12: 0 | AC12: 0 | AD12: =$D$25*$AD$9 -> 2100 | AE12: 0 | AF12: =$D$26*$AF$9 -> 360 | AG12: =$D$27*$AG$9 -> 1200 | AH12: 0 | AI12: =SUM(Y12:AH12) -> 6235 | AJ12: =AJ11 -> 1200 | AK12: =$AK$9*D12*1.5 -> 2232 | AL12: =AL11 -> 400 | AM12: 0 | AN12: =$AN$9*D12 -> 2232 | AO12: =$AO$9*D12 -> 4092 | AP12: =D12*$AP$9 -> 3720 | AQ12: =SUM(N12:AO12)-AI12-V12 -> 147462 | AR12: =AQ12*$AR$9 -> 29492.4 | AS12: =SUM(AQ12:AR12) -> 176954.4 | AT12: =(AS12*70%)*$AT$9 -> 6193.404 | AU12: =(AS12*30%)*$AU$9 -> 9555.5376 | AV12: =SUM(AS12:AU12) -> 192703.34 | AW12: =AV12-F12 -> 0
A13: 4 | B13: 7 | C13: 620 | D13: =C13*B13/1000 -> 4.34 | E13: =F13/D13 -> 49737.892 | F13: 215862.45 | G13: 78000 | H13: =F13-G13 -> 137862.45 | I13: =5*D13 -> 21.7 | J13: =I13*60 -> 1302 | K13: =J13*8 -> 10416 | L13: 3 | M13: =CONCATENATE(D13,$M$1) -> 4.34 KW | N13: =$N$9*(D13*1000) -> 110236 | O13: 24500 | P13: =L13*18*$P$9 -> 4320 | Q13: =L13*15*$Q$9 -> 3600 | R13: =L13*2*$R$9 -> 210 | S13: =B13*4*$S$9 -> 364 | T13: =L13*8*$T$9 -> 240 | U13: =$U$9/2 -> 425 | V13: =SUM(P13:U13) -> 9159 | W13: =$W$9*(D13*1000) -> 1736 | X13: =$X$9*(D13*1000) -> 1736 | Y13: =$D$23*$Y$9 -> 975 | Z13: =$D$24*$Z$9 -> 1600 | AA13: 0 | AB13: 0 | AC13: 0 | AD13: =$D$25*$AD$9 -> 2100 | AE13: 0 | AF13: =$D$26*$AF$9 -> 360 | AG13: =$D$27*$AG$9 -> 1200 | AH13: 0 | AI13: =SUM(Y13:AH13) -> 6235 | AJ13: =AJ12 -> 1200 | AK13: =$AK$9*D13*1.5 -> 2604 | AL13: =AL12 -> 400 | AM13: 0 | AN13: =$AN$9*D13 -> 2604 | AO13: =$AO$9*D13 -> 4774 | AP13: =D13*$AP$9 -> 4340 | AQ13: =SUM(N13:AO13)-AI13-V13 -> 165184 | AR13: =AQ13*$AR$9 -> 33036.8 | AS13: =SUM(AQ13:AR13) -> 198220.8 | AT13: =(AS13*70%)*$AT$9 -> 6937.728 | AU13: =(AS13*30%)*$AU$9 -> 10703.923 | AV13: =SUM(AS13:AU13) -> 215862.45 | AW13: =AV13-F13 -> 0
A14: 5 | B14: 8 | C14: 620 | D14: =C14*B14/1000 -> 4.96 | E14: =F14/D14 -> 50343.68 | F14: 249704.65 | G14: 78000 | H14: =F14-G14 -> 171704.65 | I14: =5*D14 -> 24.8 | J14: =I14*60 -> 1488 | K14: =J14*8 -> 11904 | L14: 3 | M14: =CONCATENATE(D14,$M$1) -> 4.96 KW | N14: =$N$9*(D14*1000) -> 125984 | O14: 29500 | P14: =L14*18*$P$9 -> 4320 | Q14: =L14*15*$Q$9 -> 3600 | R14: =L14*2*$R$9 -> 210 | S14: =B14*4*$S$9 -> 416 | T14: =L14*8*$T$9 -> 240 | U14: =$U$9/2 -> 425 | V14: =SUM(P14:U14) -> 9211 | W14: =$W$9*(D14*1000) -> 1984 | X14: =$X$9*(D14*1000) -> 1984 | Y14: 0 | Z14: 0 | AA14: =$H$23*$AA$9 -> 1350 | AB14: =$H$24*$AB$9 -> 2675 | AC14: 0 | AD14: =$D$30*$AD$9 -> 0 | AE14: =$H$25*$AE$9 -> 3150 | AF14: =$H$26*$AF$9 -> 360 | AG14: 0 | AH14: =$H$27*$AH$9 -> 1875 | AI14: =SUM(Y14:AH14) -> 9410 | AJ14: =AJ13 -> 1200 | AK14: =$AK$9*D14*1.5 -> 2976 | AL14: =AL13 -> 400 | AM14: 0 | AN14: =$AN$9*D14 -> 2976 | AO14: =$AO$9*D14 -> 5456 | AP14: =D14*$AP$9 -> 4960 | AQ14: =SUM(N14:AO14)-AI14-V14 -> 191081 | AR14: =AQ14*$AR$9 -> 38216.2 | AS14: =SUM(AQ14:AR14) -> 229297.2 | AT14: =(AS14*70%)*$AT$9 -> 8025.402 | AU14: =(AS14*30%)*$AU$9 -> 12382.049 | AV14: =SUM(AS14:AU14) -> 249704.65 | AW14: =AV14-F14 -> 0
A15: 6 | B15: 9 | C15: 620 | D15: =C15*B15/1000 -> 5.58 | E15: =F15/D15 -> 49553.715 | F15: 276509.73 | G15: 78000 | H15: =F15-G15 -> 198509.73 | I15: =5*D15 -> 27.9 | J15: =I15*60 -> 1674 | K15: =J15*8 -> 13392 | L15: 4 | M15: =CONCATENATE(D15,$M$1) -> 5.58 KW | N15: =$N$9*(D15*1000) -> 141732 | O15: 29500 | P15: =L15*18*$P$9 -> 5760 | Q15: =L15*15*$Q$9 -> 4800 | R15: =L15*2*$R$9 -> 280 | S15: =B15*4*$S$9 -> 468 | T15: =L15*8*$T$9 -> 320 | U15: =$U$9/2 -> 425 | V15: =SUM(P15:U15) -> 12053 | W15: =$W$9*(D15*1000) -> 2232 | X15: =$X$9*(D15*1000) -> 2232 | Y15: 0 | Z15: 0 | AA15: =$H$23*$AA$9 -> 1350 | AB15: =$H$24*$AB$9 -> 2675 | AC15: 0 | AD15: =$D$30*$AD$9 -> 0 | AE15: =$H$25*$AE$9 -> 3150 | AF15: =$H$26*$AF$9 -> 360 | AG15: 0 | AH15: =$H$27*$AH$9 -> 1875 | AI15: =SUM(Y15:AH15) -> 9410 | AJ15: =AJ14 -> 1200 | AK15: =$AK$9*D15*1.5 -> 3348 | AL15: =AL14 -> 400 | AM15: 0 | AN15: =$AN$9*D15 -> 3348 | AO15: =$AO$9*D15 -> 6138 | AP15: =D15*$AP$9 -> 5580 | AQ15: =SUM(N15:AO15)-AI15-V15 -> 211593 | AR15: =AQ15*$AR$9 -> 42318.6 | AS15: =SUM(AQ15:AR15) -> 253911.6 | AT15: =(AS15*70%)*$AT$9 -> 8886.906 | AU15: =(AS15*30%)*$AU$9 -> 13711.226 | AV15: =SUM(AS15:AU15) -> 276509.73 | AW15: =AV15-F15 -> 0
A16: 7 | B16: 10 | C16: 620 | D16: =C16*B16/1000 -> 6.2 | E16: =F16/D16 -> 48439.071 | F16: 300322.24 | G16: 78000 | H16: =F16-G16 -> 222322.24 | I16: =5*D16 -> 31 | J16: =I16*60 -> 1860 | K16: =J16*8 -> 14880 | L16: 4 | M16: =CONCATENATE(D16,$M$1) -> 6.2 KW | N16: =$N$9*(D16*1000) -> 157480 | O16: 30000 | P16: =L16*18*$P$9 -> 5760 | Q16: =L16*15*$Q$9 -> 4800 | R16: =L16*2*$R$9 -> 280 | S16: =B16*4*$S$9 -> 520 | T16: =L16*8*$T$9 -> 320 | U16: =$U$9/2 -> 425 | V16: =SUM(P16:U16) -> 12105 | W16: =$W$9*(D16*1000) -> 2480 | X16: =$X$9*(D16*1000) -> 2480 | Y16: 0 | Z16: 0 | AA16: =$H$23*$AA$9 -> 1350 | AB16: =$H$24*$AB$9 -> 2675 | AC16: 0 | AD16: =$D$30*$AD$9 -> 0 | AE16: =$H$25*$AE$9 -> 3150 | AF16: =$H$26*$AF$9 -> 360 | AG16: 0 | AH16: =$H$27*$AH$9 -> 1875 | AI16: =SUM(Y16:AH16) -> 9410 | AJ16: =AJ15 -> 1200 | AK16: =$AK$9*D16*1.5 -> 3720 | AL16: =AL15 -> 400 | AM16: 0 | AN16: =$AN$9*D16 -> 3720 | AO16: =$AO$9*D16 -> 6820 | AP16: =D16*$AP$9 -> 6200 | AQ16: =SUM(N16:AO16)-AI16-V16 -> 229815 | AR16: =AQ16*$AR$9 -> 45963 | AS16: =SUM(AQ16:AR16) -> 275778 | AT16: =(AS16*70%)*$AT$9 -> 9652.23 | AU16: =(AS16*30%)*$AU$9 -> 14892.012 | AV16: =SUM(AS16:AU16) -> 300322.24 | AW16: =AV16-F16 -> 0
A17: 8 | B17: 12 | C17: 620 | D17: =C17*B17/1000 -> 7.44 | E17: =F17/D17 -> 47650.6 | F17: 354520.47 | G17: 78000 | H17: =F17-G17 -> 276520.47 | I17: =5*D17 -> 37.2 | J17: =I17*60 -> 2232 | K17: =J17*8 -> 17856 | L17: 6 | M17: =CONCATENATE(D17,$M$1) -> 7.44 KW | N17: =$N$9*(D17*1000) -> 188976 | O17: 30500 | P17: =L17*18*$P$9 -> 8640 | Q17: =L17*15*$Q$9 -> 7200 | R17: =L17*2*$R$9 -> 420 | S17: =B17*4*$S$9 -> 624 | T17: =L17*8*$T$9 -> 480 | U17: =$U$9/2 -> 425 | V17: =SUM(P17:U17) -> 17789 | W17: =$W$9*(D17*1000) -> 2976 | X17: =$X$9*(D17*1000) -> 2976 | Y17: 0 | Z17: 0 | AA17: 0 | AB17: 0 | AC17: =$L$23*$AC$9 -> 3600 | AD17: =$D$30*$AD$9 -> 0 | AE17: =$L$25*$AE$9 -> 3150 | AF17: =$L$26*$AF$9 -> 360 | AG17: 0 | AH17: =$L$27*$AH$9 -> 2250 | AI17: =SUM(Y17:AH17) -> 9360 | AJ17: =AJ16 -> 1200 | AK17: =$AK$9*D17*1.5 -> 4464 | AL17: =AL16 -> 400 | AM17: 0 | AN17: =$AN$9*D17 -> 4464 | AO17: =$AO$9*D17 -> 8184 | AP17: =D17*$AP$9 -> 7440 | AQ17: =SUM(N17:AO17)-AI17-V17 -> 271289 | AR17: =AQ17*$AR$9 -> 54257.8 | AS17: =SUM(AQ17:AR17) -> 325546.8 | AT17: =(AS17*70%)*$AT$9 -> 11394.138 | AU17: =(AS17*30%)*$AU$9 -> 17579.527 | AV17: =SUM(AS17:AU17) -> 354520.47 | AW17: =AV17-F17 -> 0
A18: 9 | B18: 14 | C18: 620 | D18: =C18*B18/1000 -> 8.68 | E18: =F18/D18 -> 49461.627 | F18: 429326.92 | G18: 78000 | H18: =F18-G18 -> 351326.92 | I18: =5*D18 -> 43.4 | J18: =I18*60 -> 2604 | K18: =J18*8 -> 20832 | L18: 6 | M18: =CONCATENATE(D18,$M$1) -> 8.68 KW | N18: =$N$9*(D18*1000) -> 220472 | O18: 52000 | P18: =L18*18*$P$9 -> 8640 | Q18: =L18*15*$Q$9 -> 7200 | R18: =L18*2*$R$9 -> 420 | S18: =B18*4*$S$9 -> 728 | T18: =L18*8*$T$9 -> 480 | U18: =$U$9/2 -> 425 | V18: =SUM(P18:U18) -> 17893 | W18: =$W$9*(D18*1000) -> 3472 | X18: =$X$9*(D18*1000) -> 3472 | Y18: 0 | Z18: 0 | AA18: 0 | AB18: 0 | AC18: =$L$23*$AC$9 -> 3600 | AD18: =$D$30*$AD$9 -> 0 | AE18: =$L$25*$AE$9 -> 3150 | AF18: =$L$26*$AF$9 -> 360 | AG18: 0 | AH18: =$L$27*$AH$9 -> 2250 | AI18: =SUM(Y18:AH18) -> 9360 | AJ18: =AJ17 -> 1200 | AK18: =$AK$9*D18*1.5 -> 5208 | AL18: 700 | AM18: 0 | AN18: =$AN$9*D18 -> 5208 | AO18: =$AO$9*D18 -> 9548 | AP18: =D18*$AP$9 -> 8680 | AQ18: =SUM(N18:AO18)-AI18-V18 -> 328533 | AR18: =AQ18*$AR$9 -> 65706.6 | AS18: =SUM(AQ18:AR18) -> 394239.6 | AT18: =(AS18*70%)*$AT$9 -> 13798.386 | AU18: =(AS18*30%)*$AU$9 -> 21288.938 | AV18: =SUM(AS18:AU18) -> 429326.92 | AW18: =AV18-F18 -> 0
A19: 10 | B19: 16 | C19: 620 | D19: =C19*B19/1000 -> 9.92 | E19: =F19/D19 -> 48579.104 | F19: 481904.72 | G19: 78000 | H19: =F19-G19 -> 403904.72 | I19: =5*D19 -> 49.6 | J19: =I19*60 -> 2976 | K19: =J19*8 -> 23808 | L19: 7 | M19: =CONCATENATE(D19,$M$1) -> 9.92 KW | N19: =$N$9*(D19*1000) -> 251968 | O19: 54000 | P19: =L19*18*$P$9 -> 10080 | Q19: =L19*15*$Q$9 -> 8400 | R19: =L19*2*$R$9 -> 490 | S19: =B19*4*$S$9 -> 832 | T19: =L19*8*$T$9 -> 560 | U19: =$U$9/2 -> 425 | V19: =SUM(P19:U19) -> 20787 | W19: =$W$9*(D19*1000) -> 3968 | X19: =$X$9*(D19*1000) -> 3968 | Y19: 0 | Z19: 0 | AA19: 0 | AB19: 0 | AC19: =$L$23*$AC$9 -> 3600 | AD19: =$D$30*$AD$9 -> 0 | AE19: =$L$25*$AE$9 -> 3150 | AF19: =$L$26*$AF$9 -> 360 | AG19: 0 | AH19: =$L$27*$AH$9 -> 2250 | AI19: =SUM(Y19:AH19) -> 9360 | AJ19: =AJ18 -> 1200 | AK19: =$AK$9*D19*1.5 -> 5952 | AL19: 700 | AM19: 0 | AN19: =$AN$9*D19 -> 5952 | AO19: =$AO$9*D19 -> 10912 | AP19: =D19*$AP$9 -> 9920 | AQ19: =SUM(N19:AO19)-AI19-V19 -> 368767 | AR19: =AQ19*$AR$9 -> 73753.4 | AS19: =SUM(AQ19:AR19) -> 442520.4 | AT19: =(AS19*70%)*$AT$9 -> 15488.214 | AU19: =(AS19*30%)*$AU$9 -> 23896.102 | AV19: =SUM(AS19:AU19) -> 481904.72 | AW19: =AV19-F19 -> 0
A20: Electrical Item BOQ | M20: INV - SG3.0RS | O20: 15800
A21: 2 kw to 4.5 kw | E21: 5 kw to 6 kw | I21: 6 kw to 10 kw | M21: INV - SG3.6RS | O21: 15800 | W21: Electrical Item BOQ
A22: Item | D22: Quantity(MTR) | E22: Item | H22: Quantity(MTR) | I22: Item | L22: Quantity(MTR) | M22: INV - SG4.0RS | O22: 24500 | W22: 2 kw to 4.5 kw | AA22: 5 kw to 6 kw | AE22: 6 kw to 10 kw
A23: 2C X 2.5 SQMM CU.FLEX CABLE (AC) | D23: 15 | E23: 2C X 4 SQMM CU.FLEX CABLE (AC) | H23: 15 | I23: 4C X 4 SQMM CU.FLEX CABLE (AC) | L23: 18 | M23: INV - SG5.0RS | O23: 29000 | W23: Item | Z23: Quantity(MTR) | AA23: Item | AD23: Quantity(MTR) | AE23: Item | AH23: Quantity(MTR)
A24: 1C X 2.5 SQMM CU.FLEX CABLE (DC) | D24: 40 | E24: 1C X 4 SQMM CU.FLEX CABLE (DC) | H24: 50 | I24: 1C X 4 SQMM CU.FLEX CABLE (DC) | L24: 70 | M24: INV - SG6.0RS | O24: 30000 | W24: 2C X 2.5 SQMM CU.FLEX CABLE (AC) | Z24: D23 | AA24: 2C X 4 SQMM CU.FLEX CABLE (AC) | AD24: H23 | AE24: 3C X 4 SQMM CU.FLEX CABLE (AC) | AH24: L23
A25: 1C X 2.5 SQMM CU.FLEX CABLE (EARTHING) | D25: 70 | E25: 1C X 4 SQMM CU.FLEX CABLE (EARTHING) | H25: 70 | I25: 1C X 4 SQMM CU.FLEX CABLE (EARTHING) | L25: 70 | M25: INV - SG5.0RT | W25: 1C X 2.5 SQMM CU.FLEX CABLE (DC) | Z25: D24 | AA25: 1C X 4 SQMM CU.FLEX CABLE (DC) | AD25: H24 | AE25: 1C X 4 SQMM CU.FLEX CABLE (DC) | AH25: L24
A26: 1C X 16 SQMM AL.FLEX CABLE (LA) | D26: 20 | E26: 1C X 16 SQMM AL.FLEX CABLE (LA) | H26: 20 | I26: 1C X 16 SQMM AL.FLEX CABLE (LA) | L26: 20 | M26: INV - SG6.0RT | O26: 47000 | W26: 1C X 2.5 SQMM CU.FLEX CABLE (EARTHING) | Z26: D25 | AA26: 1C X 4 SQMM CU.FLEX CABLE (EARTHING) | AD26: H25 | AE26: 1C X 4 SQMM CU.FLEX CABLE (EARTHING) | AH26: L25
A27: 20 MM PVC PIPE WITH SADDLE - NOS | D27: 20 | E27: 25 MM PVC PIPE WITH SADDLE - NOS | H27: 25 | I27: 25 MM PVC PIPE WITH SADDLE - NOS | L27: 30 | M27: INV - SG8.0RT | O27: 51500 | W27: 1C X 16 SQMM AL.FLEX CABLE (LA) | Z27: D26 | AA27: 1C X 16 SQMM AL.FLEX CABLE (LA) | AD27: H26 | AE27: 1C X 16 SQMM AL.FLEX CABLE (LA) | AH27: L26
A28: 20 MM ELBO - NOS | D28: 15 | E28: 25 MM ELBO - NOS | H28: 20 | I28: 25 MM ELBO - NOS | L28: 20 | M28: INV - SG10RT | O28: 53500 | W28: 20 MM PVC PIPE WITH SADDLE - NOS | Z28: D27 | AA28: 25 MM PVC PIPE WITH SADDLE - NOS | AD28: H27 | AE28: 25 MM PVC PIPE WITH SADDLE - NOS | AH28: L27
A29: 20 MM TEE - NOS | D29: 5 | E29: 25 MM TEE - NOS | H29: 7 | I29: 25 MM TEE - NOS | L29: 7 | W29: 20 MM ELBO - NOS | Z29: D28 | AA29: 25 MM ELBO - NOS | AD29: H28 | AE29: 25 MM ELBO - NOS | AH29: L28
A30: Banking Detail | E30: Required Documents | H30: ITEM AND ITS MAKE | W30: 20 MM TEE - NOS | Z30: D29 | AA30: 25 MM TEE - NOS | AD30: H29 | AE30: 25 MM TEE - NOS | AH30: L29
A31: Bank Name : | C31: AU SMALL FINANCE BANK | E31: 1 | F31: ELECTRICITY BILL | H31: SOLAR MODULE | J31: ADANI TOPCON BI FACIAL
A32: A/C Name : | C32: HI TECH SOLAR SOLUTION | E32: 2 | F32: BANK DETAILS | H32: SOLAR INVERTER | J32: SUNGROW
A33: A/C Type : | C33: CURRENT ACCOUNT | E33: 3 | F33: AADHAR CARD | H33: ACDB & DCDB | J33: MCB :-Schneider & SPD :-Finder
A34: A/C Number : | C34: 1107865152531445 | E34: 4 | F34: PAN CARD | H34: WIRES AND CABLES | J34: DC CABLE - HAVELLS | AC CABLE - APAAR
A35: IFSC Code : | C35: AUBL0002158 | H35: Module Mounting Structure | J35: 60 MICRONES HDPGI (HINDUSTAR MAKE)
A36: Branch : | C36: DAHOD | H36: EARTHING & LA | J36: COPPER BOUNDED
A37: TEARMS AND CONDITIONS
A38: 1 | B38: Described cable length in BOQ is included in standard plant rate. If length more than from described BOQ will be charged 250RS/FEET/KW Upto 4.5 kw ,350RS/FEET/KW From 4.5 to 6 kw & 450RS/FEET/KW From 6 to 10 kw as per Actual.
A40: 2 | B40: 6 to 8 feet hight Structure is included in standard plant rate. If Structure Hight more than from described BOQ will be charged 500RS/FEET/KW As per Actual
A41: 3 | B41: Any charge of the solar meter will have to be paid by the consumer himself. Solar meter chargers are not included in this quotation.
A42: 4 | B42: Plant capacity may vary due to Solar Panel Size avilibility. Final billing amount varry accordingly.
A43: 5 | B43: Warranty: Hi tech solar solution warrants the installation workmanship for a period of 5 years from the date of commissioning. Solar panels,Inverter,MCB,Fuse & cartridges and other equipment are subject to manufacturer warranties, details of which will be provided upon installation.
A46: 6 | B46: We will repair or, if found necessary replace a defective component of solar system for failure due to manufacturing defects & The repaired/replaced part or Solar system does not carry a new warranty
...

Sheet PL Pahal (TOPCON)
M1: KW
A2: Quotation / Price List For Residential RTS System Under PM : Surya Ghar Muft Bijli Yojna | M2: SOLAR PLANT BOQ
A3: Name : | H3: Consumer No :
A5: Address: | H5: Contact No: | M5: ITEMS | N5: MODULE | O5: INVERTER | P5: STRUCTURE | W5: ACDB | X5: DCDB | Y5: CABLING | AJ5: EARTHING KIT | AK5: CIVIL WORK | AL5: TRANSPORT | AM5: METER FEES | AN5: ELECTRIFICATION | AO5: FABRICATION | AP5: OTHER MISC. | AQ5: TOTAL | AR5: COMISSIONING CHARGES | AS5: TAXABLE VALUE | AT5: GST (70%) | AU5: GST (5.7%) | AV5: GRAND TOTAL
B8: Type of Solar Panels | E8: Solar RoofTop System Pricing | I8: System generation & Revenue Details | L8: Structure BOQ | P8: 60 x 40 HDGI PIPE | Q8: 40 X 40 HDGI PIPE | R8: BASE PLATE 125X125 4 MM | S8: J BOULT | T8: WEDGE ANCORE BOULT | U8: CHEMICAL BOTTLE | V8: TOTAL | Y8: AC -2CX2.5 SQMM | Z8: DC -1CX2.5 SQMM | AA8: AC -2CX4.0 SQMM | AB8: DC -1CX4 SQMM | AC8: AC - 4CX4SQMM | AD8: ERT - 1CX2.5 SQMM | AE8: ERT - 1CX4 SQMM | AF8: L.A - 1CX16SQMM | AG8: 20MM PIPE | AH8: 25MM PIPE | AI8: TOTAL
A9: SR NO | B9: No of Module | C9: Module Wattage | D9: DC Capacity (kw) | E9: Discover Rate | F9: Total (Inc.GST) | G9: Subsidy | H9: Basic Plant Cost (-subsidy rate) | I9: Unit Generation / Day | J9: 2 Months Generation (Unit) | K9: 2 Months Saving (INR) | L9: No of HDPGI Pipe Incluid Size(60 x 40) & (40 x 40) | M9: RATE | N9: 23.4 | O9: 5 | P9: 80 | Q9: 80 | R9: 35 | S9: 13 | T9: 10 | U9: 850 | W9: 0.4 | X9: 0.4 | Y9: 65 | Z9: 40 | AA9: 90 | AB9: 53.5 | AC9: 200 | AD9: 30 | AE9: 45 | AF9: 18 | AG9: 60 | AH9: 75 | AJ9: 1200 | AK9: 400 | AL9: 400 | AM9: 0 | AN9: 600 | AO9: 1100 | AP9: 1000 | AR9: 0.2 | AT9: 0.05 | AU9: 0.18
A10: 1 | B10: 4 | C10: 600 | D10: =C10*B10/1000 -> 2.4 | E10: =F10/D10 -> 52597.611 | F10: 126234.27 | G10: =60000+(18000*(D10-2)) -> 67200 | H10: =F10-G10 -> 59034.266 | I10: =5*D10 -> 12 | J10: =I10*60 -> 720 | K10: =J10*8 -> 5760 | L10: 3 | M10: =CONCATENATE(D10,$M$1) -> 2.4 KW | N10: =$N$9*(D10*1000) -> 56160 | O10: 15300 | P10: =L10*18*$P$9 -> 4320 | Q10: =L10*15*$Q$9 -> 3600 | R10: =L10*2*$R$9 -> 210 | S10: =B10*4*$S$9 -> 208 | T10: =L10*8*$T$9 -> 240 | U10: =$U$9/2 -> 425 | V10: =SUM(P10:U10) -> 9003 | W10: 1200 | X10: =$X$9*(D10*1000) -> 960 | Y10: =$D$23*$Y$9 -> 975 | Z10: =$D$24*$Z$9 -> 1600 | AA10: 0 | AB10: 0 | AC10: 0 | AD10: =$D$25*$AD$9 -> 2100 | AE10: 0 | AF10: =$D$26*$AF$9 -> 360 | AG10: =$D$27*$AG$9 -> 1200 | AH10: 0 | AI10: =SUM(Y10:AH10) -> 6235 | AJ10: =AJ9 -> 1200 | AK10: 1500 | AL10: =AL9 -> 400 | AM10: 0 | AN10: =$AN$9*D10 -> 1440 | AO10: 3200 | AP10: =D10*$AP$9 -> 2400 | AQ10: =SUM(N10:AO10)-AI10-V10 -> 96598 | AR10: =AQ10*$AR$9 -> 19319.6 | AS10: =SUM(AQ10:AR10) -> 115917.6 | AT10: =(AS10*70%)*$AT$9 -> 4057.116 | AU10: =(AS10*30%)*$AU$9 -> 6259.5504 | AV10: =SUM(AS10:AU10) -> 126234.27 | AW10: =AV10-F10 -> 0
A11: 2 | B11: 5 | C11: 600 | D11: =C11*B11/1000 -> 3 | E11: =F11/D11 -> 48565.044 | F11: 145695.13 | G11: 78000 | H11: =F11-G11 -> 67695.132 | I11: =5*D11 -> 15 | J11: =I11*60 -> 900 | K11: =J11*8 -> 7200 | L11: 3 | M11: =CONCATENATE(D11,$M$1) -> 3 KW | N11: =$N$9*(D11*1000) -> 70200 | O11: 15500 | P11: =L11*18*$P$9 -> 4320 | Q11: =L11*15*$Q$9 -> 3600 | R11: =L11*2*$R$9 -> 210 | S11: =B11*4*$S$9 -> 260 | T11: =L11*8*$T$9 -> 240 | U11: =$U$9/2 -> 425 | V11: =SUM(P11:U11) -> 9055 | W11: 1200 | X11: =$X$9*(D11*1000) -> 1200 | Y11: =$D$23*$Y$9 -> 975 | Z11: =$D$24*$Z$9 -> 1600 | AA11: 0 | AB11: 0 | AC11: 0 | AD11: =$D$25*$AD$9 -> 2100 | AE11: 0 | AF11: =$D$26*$AF$9 -> 360 | AG11: =$D$27*$AG$9 -> 1200 | AH11: 0 | AI11: =SUM(Y11:AH11) -> 6235 | AJ11: =AJ10 -> 1200 | AK11: 1500 | AL11: =AL10 -> 400 | AM11: 0 | AN11: =$AN$9*D11 -> 1800 | AO11: 3200 | AP11: =D11*$AP$9 -> 3000 | AQ11: =SUM(N11:AO11)-AI11-V11 -> 111490 | AR11: =AQ11*$AR$9 -> 22298 | AS11: =SUM(AQ11:AR11) -> 133788 | AT11: =(AS11*70%)*$AT$9 -> 4682.58 | AU11: =(AS11*30%)*$AU$9 -> 7224.552 | AV11: =SUM(AS11:AU11) -> 145695.13 | AW11: =AV11-F11 -> 0
A12: 3 | B12: 6 | C12: 600 | D12: =C12*B12/1000 -> 3.6 | E12: =F12/D12 -> 46406.646 | F12: 167063.93 | G12: 78000 | H12: =F12-G12 -> 89063.926 | I12: =5*D12 -> 18 | J12: =I12*60 -> 1080 | K12: =J12*8 -> 8640 | L12: 3 | M12: =CONCATENATE(D12,$M$1) -> 3.6 KW | N12: =$N$9*(D12*1000) -> 84240 | O12: 15500 | P12: =L12*18*$P$9 -> 4320 | Q12: =L12*15*$Q$9 -> 3600 | R12: =L12*2*$R$9 -> 210 | S12: =B12*4*$S$9 -> 312 | T12: =L12*8*$T$9 -> 240 | U12: =$U$9/2 -> 425 | V12: =SUM(P12:U12) -> 9107 | W12: =$W$9*(D12*1000) -> 1440 | X12: =$X$9*(D12*1000) -> 1440 | Y12: =$D$23*$Y$9 -> 975 | Z12: =$D$24*$Z$9 -> 1600 | AA12: 0 | AB12: 0 | AC12: 0 | AD12: =$D$25*$AD$9 -> 2100 | AE12: 0 | AF12: =$D$26*$AF$9 -> 360 | AG12: =$D$27*$AG$9 -> 1200 | AH12: 0 | AI12: =SUM(Y12:AH12) -> 6235 | AJ12: =AJ11 -> 1200 | AK12: =$AK$9*D12*1.5 -> 2160 | AL12: =AL11 -> 400 | AM12: 0 | AN12: =$AN$9*D12 -> 2160 | AO12: =$AO$9*D12 -> 3960 | AP12: =D12*$AP$9 -> 3600 | AQ12: =SUM(N12:AO12)-AI12-V12 -> 127842 | AR12: =AQ12*$AR$9 -> 25568.4 | AS12: =SUM(AQ12:AR12) -> 153410.4 | AT12: =(AS12*70%)*$AT$9 -> 5369.364 | AU12: =(AS12*30%)*$AU$9 -> 8284.1616 | AV12: =SUM(AS12:AU12) -> 167063.93 | AW12: =AV12-F12 -> 0
A13: 4 | B13: 7 | C13: 600 | D13: =C13*B13/1000 -> 4.2 | E13: =F13/D13 -> 47540.762 | F13: 199671.2 | G13: 78000 | H13: =F13-G13 -> 121671.2 | I13: =5*D13 -> 21 | J13: =I13*60 -> 1260 | K13: =J13*8 -> 10080 | L13: 3 | M13: =CONCATENATE(D13,$M$1) -> 4.2 KW | N13: =$N$9*(D13*1000) -> 98280 | O13: 24500 | P13: =L13*18*$P$9 -> 4320 | Q13: =L13*15*$Q$9 -> 3600 | R13: =L13*2*$R$9 -> 210 | S13: =B13*4*$S$9 -> 364 | T13: =L13*8*$T$9 -> 240 | U13: =$U$9/2 -> 425 | V13: =SUM(P13:U13) -> 9159 | W13: =$W$9*(D13*1000) -> 1680 | X13: =$X$9*(D13*1000) -> 1680 | Y13: =$D$23*$Y$9 -> 975 | Z13: =$D$24*$Z$9 -> 1600 | AA13: 0 | AB13: 0 | AC13: 0 | AD13: =$D$25*$AD$9 -> 2100 | AE13: 0 | AF13: =$D$26*$AF$9 -> 360 | AG13: =$D$27*$AG$9 -> 1200 | AH13: 0 | AI13: =SUM(Y13:AH13) -> 6235 | AJ13: =AJ12 -> 1200 | AK13: =$AK$9*D13*1.5 -> 2520 | AL13: =AL12 -> 400 | AM13: 0 | AN13: =$AN$9*D13 -> 2520 | AO13: =$AO$9*D13 -> 4620 | AP13: =D13*$AP$9 -> 4200 | AQ13: =SUM(N13:AO13)-AI13-V13 -> 152794 | AR13: =AQ13*$AR$9 -> 30558.8 | AS13: =SUM(AQ13:AR13) -> 183352.8 | AT13: =(AS13*70%)*$AT$9 -> 6417.348 | AU13: =(AS13*30%)*$AU$9 -> 9901.0512 | AV13: =SUM(AS13:AU13) -> 199671.2 | AW13: =AV13-F13 -> 0
A14: 5 | B14: 8 | C14: 600 | D14: =C14*B14/1000 -> 4.8 | E14: =F14/D14 -> 48166.742 | F14: 231200.36 | G14: 78000 | H14: =F14-G14 -> 153200.36 | I14: =5*D14 -> 24 | J14: =I14*60 -> 1440 | K14: =J14*8 -> 11520 | L14: 3 | M14: =CONCATENATE(D14,$M$1) -> 4.8 KW | N14: =$N$9*(D14*1000) -> 112320 | O14: 29500 | P14: =L14*18*$P$9 -> 4320 | Q14: =L14*15*$Q$9 -> 3600 | R14: =L14*2*$R$9 -> 210 | S14: =B14*4*$S$9 -> 416 | T14: =L14*8*$T$9 -> 240 | U14: =$U$9/2 -> 425 | V14: =SUM(P14:U14) -> 9211 | W14: =$W$9*(D14*1000) -> 1920 | X14: =$X$9*(D14*1000) -> 1920 | Y14: 0 | Z14: 0 | AA14: =$H$23*$AA$9 -> 1350 | AB14: =$H$24*$AB$9 -> 2675 | AC14: 0 | AD14: =$D$30*$AD$9 -> 0 | AE14: =$H$25*$AE$9 -> 3150 | AF14: =$H$26*$AF$9 -> 360 | AG14: 0 | AH14: =$H$27*$AH$9 -> 1875 | AI14: =SUM(Y14:AH14) -> 9410 | AJ14: =AJ13 -> 1200 | AK14: =$AK$9*D14*1.5 -> 2880 | AL14: =AL13 -> 400 | AM14: 0 | AN14: =$AN$9*D14 -> 2880 | AO14: =$AO$9*D14 -> 5280 | AP14: =D14*$AP$9 -> 4800 | AQ14: =SUM(N14:AO14)-AI14-V14 -> 176921 | AR14: =AQ14*$AR$9 -> 35384.2 | AS14: =SUM(AQ14:AR14) -> 212305.2 | AT14: =(AS14*70%)*$AT$9 -> 7430.682 | AU14: =(AS14*30%)*$AU$9 -> 11464.481 | AV14: =SUM(AS14:AU14) -> 231200.36 | AW14: =AV14-F14 -> 0
